 * Running on http://0.0.0.0:3333/ (Press CTRL+C to quit)
 * Restarting with stat
 * Debugger is active!
 * Debugger PIN: 478-161-364
60.24.91.182 - - [24/Feb/2018 13:38:56] "GET /admin/ HTTP/1.1" 200 -
60.24.91.182 - - [24/Feb/2018 13:38:58] "GET /static/base/images/logo.png HTTP/1.1" 200 -
127.0.0.1 - - [24/Feb/2018 13:41:28] "GET / HTTP/1.0" 404 -
127.0.0.1 - - [24/Feb/2018 13:41:28] "GET /admin/ HTTP/1.0" 200 -
127.0.0.1 - - [24/Feb/2018 13:41:28] "GET /admin/ HTTP/1.0" 200 -
127.0.0.1 - - [24/Feb/2018 13:41:28] "GET /admin/ HTTP/1.0" 200 -
127.0.0.1 - - [24/Feb/2018 13:41:29] "GET /admin/ HTTP/1.0" 200 -
127.0.0.1 - - [24/Feb/2018 13:41:29] "GET /admin/ HTTP/1.0" 200 -
127.0.0.1 - - [24/Feb/2018 13:41:29] "GET /admin/ HTTP/1.0" 200 -
127.0.0.1 - - [24/Feb/2018 13:41:29] "GET / HTTP/1.0" 404 -
127.0.0.1 - - [24/Feb/2018 13:41:29] "GET /admin/ HTTP/1.0" 200 -
127.0.0.1 - - [24/Feb/2018 13:41:29] "GET /favicon.ico HTTP/1.0" 404 -
127.0.0.1 - - [24/Feb/2018 13:41:50] "GET /admin/admin/list/1/ HTTP/1.0" 200 -
60.24.91.182 - - [24/Feb/2018 13:42:24] "GET /admin/trans/add/ HTTP/1.1" 200 -
60.24.91.182 - - [24/Feb/2018 13:42:24] "GET /static/calcu/images/spinner.png HTTP/1.1" 404 -
127.0.0.1 - - [24/Feb/2018 13:42:27] "GET /admin/admin/list/1/ HTTP/1.0" 200 -
127.0.0.1 - - [24/Feb/2018 13:42:34] "GET /admin/demo/ HTTP/1.0" 404 -
127.0.0.1 - - [24/Feb/2018 13:42:35] "GET /1/ HTTP/1.0" 500 -
Traceback (most recent call last):
  File "/usr/local/python3/lib/python3.5/site-packages/flask/app.py", line 1997, in __call__
    return self.wsgi_app(environ, start_response)
  File "/usr/local/python3/lib/python3.5/site-packages/flask/app.py", line 1985, in wsgi_app
    response = self.handle_exception(e)
  File "/usr/local/python3/lib/python3.5/site-packages/flask/app.py", line 1540, in handle_exception
    reraise(exc_type, exc_value, tb)
  File "/usr/local/python3/lib/python3.5/site-packages/flask/_compat.py", line 33, in reraise
    raise value
  File "/usr/local/python3/lib/python3.5/site-packages/flask/app.py", line 1982, in wsgi_app
    response = self.full_dispatch_request()
  File "/usr/local/python3/lib/python3.5/site-packages/flask/app.py", line 1614, in full_dispatch_request
    rv = self.handle_user_exception(e)
  File "/usr/local/python3/lib/python3.5/site-packages/flask/app.py", line 1517, in handle_user_exception
    reraise(exc_type, exc_value, tb)
  File "/usr/local/python3/lib/python3.5/site-packages/flask/_compat.py", line 33, in reraise
    raise value
  File "/usr/local/python3/lib/python3.5/site-packages/flask/app.py", line 1612, in full_dispatch_request
    rv = self.dispatch_request()
  File "/usr/local/python3/lib/python3.5/site-packages/flask/app.py", line 1598, in dispatch_request
    return self.view_functions[rule.endpoint](**req.view_args)
  File "/usr/local/nginx/html/solution_project/app/home/views.py", line 179, in index
    tags = Tag.query.all()
NameError: name 'Tag' is not defined
127.0.0.1 - - [24/Feb/2018 13:42:35] "GET /1/?__debugger__=yes&cmd=resource&f=style.css HTTP/1.0" 200 -
127.0.0.1 - - [24/Feb/2018 13:42:35] "GET /1/?__debugger__=yes&cmd=resource&f=jquery.js HTTP/1.0" 200 -
127.0.0.1 - - [24/Feb/2018 13:42:35] "GET /1/?__debugger__=yes&cmd=resource&f=debugger.js HTTP/1.0" 200 -
127.0.0.1 - - [24/Feb/2018 13:42:35] "GET /1/?__debugger__=yes&cmd=resource&f=ubuntu.ttf HTTP/1.0" 200 -
127.0.0.1 - - [24/Feb/2018 13:42:36] "GET /1/?__debugger__=yes&cmd=resource&f=console.png HTTP/1.0" 200 -
127.0.0.1 - - [24/Feb/2018 13:42:41] "GET /admin/admin/list/1/ HTTP/1.0" 200 -
127.0.0.1 - - [24/Feb/2018 13:42:43] "GET /admin/admin/list/1/ HTTP/1.0" 200 -
60.24.91.182 - - [24/Feb/2018 13:43:09] "POST /admin/trans/add/ HTTP/1.1" 500 -
Traceback (most recent call last):
  File "/usr/local/python3/lib/python3.5/site-packages/flask/app.py", line 1997, in __call__
    return self.wsgi_app(environ, start_response)
  File "/usr/local/python3/lib/python3.5/site-packages/flask/app.py", line 1985, in wsgi_app
    response = self.handle_exception(e)
  File "/usr/local/python3/lib/python3.5/site-packages/flask/app.py", line 1540, in handle_exception
    reraise(exc_type, exc_value, tb)
  File "/usr/local/python3/lib/python3.5/site-packages/flask/_compat.py", line 33, in reraise
    raise value
  File "/usr/local/python3/lib/python3.5/site-packages/flask/app.py", line 1982, in wsgi_app
    response = self.full_dispatch_request()
  File "/usr/local/python3/lib/python3.5/site-packages/flask/app.py", line 1614, in full_dispatch_request
    rv = self.handle_user_exception(e)
  File "/usr/local/python3/lib/python3.5/site-packages/flask/app.py", line 1517, in handle_user_exception
    reraise(exc_type, exc_value, tb)
  File "/usr/local/python3/lib/python3.5/site-packages/flask/_compat.py", line 33, in reraise
    raise value
  File "/usr/local/python3/lib/python3.5/site-packages/flask/app.py", line 1612, in full_dispatch_request
    rv = self.dispatch_request()
  File "/usr/local/python3/lib/python3.5/site-packages/flask/app.py", line 1598, in dispatch_request
    return self.view_functions[rule.endpoint](**req.view_args)
  File "/usr/local/nginx/html/solution_project/app/admin/views.py", line 48, in decorated_function
    return f(*args, **kwargs)
  File "/usr/local/nginx/html/solution_project/app/admin/views.py", line 70, in decorated_function
    return f(*args, **kwargs)
  File "/usr/local/nginx/html/solution_project/app/admin/views.py", line 565, in trans_add
    db.session.commit()
  File "/usr/local/python3/lib/python3.5/site-packages/sqlalchemy/orm/scoping.py", line 153, in do
    return getattr(self.registry(), name)(*args, **kwargs)
  File "/usr/local/python3/lib/python3.5/site-packages/sqlalchemy/orm/session.py", line 943, in commit
    self.transaction.commit()
  File "/usr/local/python3/lib/python3.5/site-packages/sqlalchemy/orm/session.py", line 467, in commit
    self._prepare_impl()
  File "/usr/local/python3/lib/python3.5/site-packages/sqlalchemy/orm/session.py", line 447, in _prepare_impl
    self.session.flush()
  File "/usr/local/python3/lib/python3.5/site-packages/sqlalchemy/orm/session.py", line 2243, in flush
    self._flush(objects)
  File "/usr/local/python3/lib/python3.5/site-packages/sqlalchemy/orm/session.py", line 2369, in _flush
    transaction.rollback(_capture_exception=True)
  File "/usr/local/python3/lib/python3.5/site-packages/sqlalchemy/util/langhelpers.py", line 66, in __exit__
    compat.reraise(exc_type, exc_value, exc_tb)
  File "/usr/local/python3/lib/python3.5/site-packages/sqlalchemy/util/compat.py", line 187, in reraise
    raise value
  File "/usr/local/python3/lib/python3.5/site-packages/sqlalchemy/orm/session.py", line 2333, in _flush
    flush_context.execute()
  File "/usr/local/python3/lib/python3.5/site-packages/sqlalchemy/orm/unitofwork.py", line 391, in execute
    rec.execute(self)
  File "/usr/local/python3/lib/python3.5/site-packages/sqlalchemy/orm/unitofwork.py", line 556, in execute
    uow
  File "/usr/local/python3/lib/python3.5/site-packages/sqlalchemy/orm/persistence.py", line 181, in save_obj
    mapper, table, insert)
  File "/usr/local/python3/lib/python3.5/site-packages/sqlalchemy/orm/persistence.py", line 866, in _emit_insert_statements
    execute(statement, params)
  File "/usr/local/python3/lib/python3.5/site-packages/sqlalchemy/engine/base.py", line 948, in execute
    return meth(self, multiparams, params)
  File "/usr/local/python3/lib/python3.5/site-packages/sqlalchemy/sql/elements.py", line 269, in _execute_on_connection
    return connection._execute_clauseelement(self, multiparams, params)
  File "/usr/local/python3/lib/python3.5/site-packages/sqlalchemy/engine/base.py", line 1060, in _execute_clauseelement
    compiled_sql, distilled_params
  File "/usr/local/python3/lib/python3.5/site-packages/sqlalchemy/engine/base.py", line 1200, in _execute_context
    context)
  File "/usr/local/python3/lib/python3.5/site-packages/sqlalchemy/engine/base.py", line 1413, in _handle_dbapi_exception
    exc_info
  File "/usr/local/python3/lib/python3.5/site-packages/sqlalchemy/util/compat.py", line 203, in raise_from_cause
    reraise(type(exception), exception, tb=exc_tb, cause=cause)
  File "/usr/local/python3/lib/python3.5/site-packages/sqlalchemy/util/compat.py", line 186, in reraise
    raise value.with_traceback(tb)
  File "/usr/local/python3/lib/python3.5/site-packages/sqlalchemy/engine/base.py", line 1193, in _execute_context
    context)
  File "/usr/local/python3/lib/python3.5/site-packages/sqlalchemy/engine/default.py", line 507, in do_execute
    cursor.execute(statement, parameters)
sqlalchemy.exc.DatabaseError: (cx_Oracle.DatabaseError) ORA-01861: 文字与格式字符串不匹配 [SQL: 'INSERT INTO tbl_trans_things_num_temp (station_name, per_box_num, box_num, order_date, import_by) VALUES (:station_name, :per_box_num, :box_num, :order_date, :import_by) RETURNING tbl_trans_things_num_temp.things_id INTO :ret_0'] [parameters: {'import_by': 'admin', 'per_box_num': 0.0, 'ret_0': <cx_Oracle.STRING with value [None, None, None, None, None, None, None, None, None, None, None, None, None, None, None, None, None, None, None, None,  ... (30 characters truncated) ... None, None, None, None, None, None, None, None, None, None, None, None, None, None, None, None, None, None, None, None, None, None, None, None, None]>, 'station_name': '白各庄', 'box_num': 0.0, 'order_date': '2018-02-24'}] (Background on this error at: http://sqlalche.me/e/4xp6)
60.24.91.182 - - [24/Feb/2018 13:44:14] "POST /admin/trans/add/ HTTP/1.1" 500 -
Traceback (most recent call last):
  File "/usr/local/python3/lib/python3.5/site-packages/flask/app.py", line 1997, in __call__
    return self.wsgi_app(environ, start_response)
  File "/usr/local/python3/lib/python3.5/site-packages/flask/app.py", line 1985, in wsgi_app
    response = self.handle_exception(e)
  File "/usr/local/python3/lib/python3.5/site-packages/flask/app.py", line 1540, in handle_exception
    reraise(exc_type, exc_value, tb)
  File "/usr/local/python3/lib/python3.5/site-packages/flask/_compat.py", line 33, in reraise
    raise value
  File "/usr/local/python3/lib/python3.5/site-packages/flask/app.py", line 1982, in wsgi_app
    response = self.full_dispatch_request()
  File "/usr/local/python3/lib/python3.5/site-packages/flask/app.py", line 1614, in full_dispatch_request
    rv = self.handle_user_exception(e)
  File "/usr/local/python3/lib/python3.5/site-packages/flask/app.py", line 1517, in handle_user_exception
    reraise(exc_type, exc_value, tb)
  File "/usr/local/python3/lib/python3.5/site-packages/flask/_compat.py", line 33, in reraise
    raise value
  File "/usr/local/python3/lib/python3.5/site-packages/flask/app.py", line 1612, in full_dispatch_request
    rv = self.dispatch_request()
  File "/usr/local/python3/lib/python3.5/site-packages/flask/app.py", line 1598, in dispatch_request
    return self.view_functions[rule.endpoint](**req.view_args)
  File "/usr/local/nginx/html/solution_project/app/admin/views.py", line 48, in decorated_function
    return f(*args, **kwargs)
  File "/usr/local/nginx/html/solution_project/app/admin/views.py", line 70, in decorated_function
    return f(*args, **kwargs)
  File "/usr/local/nginx/html/solution_project/app/admin/views.py", line 565, in trans_add
    db.session.commit()
  File "/usr/local/python3/lib/python3.5/site-packages/sqlalchemy/orm/scoping.py", line 153, in do
    return getattr(self.registry(), name)(*args, **kwargs)
  File "/usr/local/python3/lib/python3.5/site-packages/sqlalchemy/orm/session.py", line 943, in commit
    self.transaction.commit()
  File "/usr/local/python3/lib/python3.5/site-packages/sqlalchemy/orm/session.py", line 467, in commit
    self._prepare_impl()
  File "/usr/local/python3/lib/python3.5/site-packages/sqlalchemy/orm/session.py", line 447, in _prepare_impl
    self.session.flush()
  File "/usr/local/python3/lib/python3.5/site-packages/sqlalchemy/orm/session.py", line 2243, in flush
    self._flush(objects)
  File "/usr/local/python3/lib/python3.5/site-packages/sqlalchemy/orm/session.py", line 2369, in _flush
    transaction.rollback(_capture_exception=True)
  File "/usr/local/python3/lib/python3.5/site-packages/sqlalchemy/util/langhelpers.py", line 66, in __exit__
    compat.reraise(exc_type, exc_value, exc_tb)
  File "/usr/local/python3/lib/python3.5/site-packages/sqlalchemy/util/compat.py", line 187, in reraise
    raise value
  File "/usr/local/python3/lib/python3.5/site-packages/sqlalchemy/orm/session.py", line 2333, in _flush
    flush_context.execute()
  File "/usr/local/python3/lib/python3.5/site-packages/sqlalchemy/orm/unitofwork.py", line 391, in execute
    rec.execute(self)
  File "/usr/local/python3/lib/python3.5/site-packages/sqlalchemy/orm/unitofwork.py", line 556, in execute
    uow
  File "/usr/local/python3/lib/python3.5/site-packages/sqlalchemy/orm/persistence.py", line 181, in save_obj
    mapper, table, insert)
  File "/usr/local/python3/lib/python3.5/site-packages/sqlalchemy/orm/persistence.py", line 866, in _emit_insert_statements
    execute(statement, params)
  File "/usr/local/python3/lib/python3.5/site-packages/sqlalchemy/engine/base.py", line 948, in execute
    return meth(self, multiparams, params)
  File "/usr/local/python3/lib/python3.5/site-packages/sqlalchemy/sql/elements.py", line 269, in _execute_on_connection
    return connection._execute_clauseelement(self, multiparams, params)
  File "/usr/local/python3/lib/python3.5/site-packages/sqlalchemy/engine/base.py", line 1060, in _execute_clauseelement
    compiled_sql, distilled_params
  File "/usr/local/python3/lib/python3.5/site-packages/sqlalchemy/engine/base.py", line 1200, in _execute_context
    context)
  File "/usr/local/python3/lib/python3.5/site-packages/sqlalchemy/engine/base.py", line 1413, in _handle_dbapi_exception
    exc_info
  File "/usr/local/python3/lib/python3.5/site-packages/sqlalchemy/util/compat.py", line 203, in raise_from_cause
    reraise(type(exception), exception, tb=exc_tb, cause=cause)
  File "/usr/local/python3/lib/python3.5/site-packages/sqlalchemy/util/compat.py", line 186, in reraise
    raise value.with_traceback(tb)
  File "/usr/local/python3/lib/python3.5/site-packages/sqlalchemy/engine/base.py", line 1193, in _execute_context
    context)
  File "/usr/local/python3/lib/python3.5/site-packages/sqlalchemy/engine/default.py", line 507, in do_execute
    cursor.execute(statement, parameters)
sqlalchemy.exc.DatabaseError: (cx_Oracle.DatabaseError) ORA-01861: 文字与格式字符串不匹配 [SQL: 'INSERT INTO tbl_trans_things_num_temp (station_name, per_box_num, box_num, order_date, import_by) VALUES (:station_name, :per_box_num, :box_num, :order_date, :import_by) RETURNING tbl_trans_things_num_temp.things_id INTO :ret_0'] [parameters: {'import_by': 'admin', 'per_box_num': 0.0, 'ret_0': <cx_Oracle.STRING with value [None, None, None, None, None, None, None, None, None, None, None, None, None, None, None, None, None, None, None, None,  ... (30 characters truncated) ... None, None, None, None, None, None, None, None, None, None, None, None, None, None, None, None, None, None, None, None, None, None, None, None, None]>, 'station_name': '白各庄', 'box_num': 0.0, 'order_date': '2018-02-24'}] (Background on this error at: http://sqlalche.me/e/4xp6)
60.24.91.182 - - [24/Feb/2018 13:44:15] "POST /admin/trans/add/ HTTP/1.1" 500 -
Traceback (most recent call last):
  File "/usr/local/python3/lib/python3.5/site-packages/flask/app.py", line 1997, in __call__
    return self.wsgi_app(environ, start_response)
  File "/usr/local/python3/lib/python3.5/site-packages/flask/app.py", line 1985, in wsgi_app
    response = self.handle_exception(e)
  File "/usr/local/python3/lib/python3.5/site-packages/flask/app.py", line 1540, in handle_exception
    reraise(exc_type, exc_value, tb)
  File "/usr/local/python3/lib/python3.5/site-packages/flask/_compat.py", line 33, in reraise
    raise value
  File "/usr/local/python3/lib/python3.5/site-packages/flask/app.py", line 1982, in wsgi_app
    response = self.full_dispatch_request()
  File "/usr/local/python3/lib/python3.5/site-packages/flask/app.py", line 1614, in full_dispatch_request
    rv = self.handle_user_exception(e)
  File "/usr/local/python3/lib/python3.5/site-packages/flask/app.py", line 1517, in handle_user_exception
    reraise(exc_type, exc_value, tb)
  File "/usr/local/python3/lib/python3.5/site-packages/flask/_compat.py", line 33, in reraise
    raise value
  File "/usr/local/python3/lib/python3.5/site-packages/flask/app.py", line 1612, in full_dispatch_request
    rv = self.dispatch_request()
  File "/usr/local/python3/lib/python3.5/site-packages/flask/app.py", line 1598, in dispatch_request
    return self.view_functions[rule.endpoint](**req.view_args)
  File "/usr/local/nginx/html/solution_project/app/admin/views.py", line 48, in decorated_function
    return f(*args, **kwargs)
  File "/usr/local/nginx/html/solution_project/app/admin/views.py", line 70, in decorated_function
    return f(*args, **kwargs)
  File "/usr/local/nginx/html/solution_project/app/admin/views.py", line 565, in trans_add
    db.session.commit()
  File "/usr/local/python3/lib/python3.5/site-packages/sqlalchemy/orm/scoping.py", line 153, in do
    return getattr(self.registry(), name)(*args, **kwargs)
  File "/usr/local/python3/lib/python3.5/site-packages/sqlalchemy/orm/session.py", line 943, in commit
    self.transaction.commit()
  File "/usr/local/python3/lib/python3.5/site-packages/sqlalchemy/orm/session.py", line 467, in commit
    self._prepare_impl()
  File "/usr/local/python3/lib/python3.5/site-packages/sqlalchemy/orm/session.py", line 447, in _prepare_impl
    self.session.flush()
  File "/usr/local/python3/lib/python3.5/site-packages/sqlalchemy/orm/session.py", line 2243, in flush
    self._flush(objects)
  File "/usr/local/python3/lib/python3.5/site-packages/sqlalchemy/orm/session.py", line 2369, in _flush
    transaction.rollback(_capture_exception=True)
  File "/usr/local/python3/lib/python3.5/site-packages/sqlalchemy/util/langhelpers.py", line 66, in __exit__
    compat.reraise(exc_type, exc_value, exc_tb)
  File "/usr/local/python3/lib/python3.5/site-packages/sqlalchemy/util/compat.py", line 187, in reraise
    raise value
  File "/usr/local/python3/lib/python3.5/site-packages/sqlalchemy/orm/session.py", line 2333, in _flush
    flush_context.execute()
  File "/usr/local/python3/lib/python3.5/site-packages/sqlalchemy/orm/unitofwork.py", line 391, in execute
    rec.execute(self)
  File "/usr/local/python3/lib/python3.5/site-packages/sqlalchemy/orm/unitofwork.py", line 556, in execute
    uow
  File "/usr/local/python3/lib/python3.5/site-packages/sqlalchemy/orm/persistence.py", line 181, in save_obj
    mapper, table, insert)
  File "/usr/local/python3/lib/python3.5/site-packages/sqlalchemy/orm/persistence.py", line 866, in _emit_insert_statements
    execute(statement, params)
  File "/usr/local/python3/lib/python3.5/site-packages/sqlalchemy/engine/base.py", line 948, in execute
    return meth(self, multiparams, params)
  File "/usr/local/python3/lib/python3.5/site-packages/sqlalchemy/sql/elements.py", line 269, in _execute_on_connection
    return connection._execute_clauseelement(self, multiparams, params)
  File "/usr/local/python3/lib/python3.5/site-packages/sqlalchemy/engine/base.py", line 1060, in _execute_clauseelement
    compiled_sql, distilled_params
  File "/usr/local/python3/lib/python3.5/site-packages/sqlalchemy/engine/base.py", line 1200, in _execute_context
    context)
  File "/usr/local/python3/lib/python3.5/site-packages/sqlalchemy/engine/base.py", line 1413, in _handle_dbapi_exception
    exc_info
  File "/usr/local/python3/lib/python3.5/site-packages/sqlalchemy/util/compat.py", line 203, in raise_from_cause
    reraise(type(exception), exception, tb=exc_tb, cause=cause)
  File "/usr/local/python3/lib/python3.5/site-packages/sqlalchemy/util/compat.py", line 186, in reraise
    raise value.with_traceback(tb)
  File "/usr/local/python3/lib/python3.5/site-packages/sqlalchemy/engine/base.py", line 1193, in _execute_context
    context)
  File "/usr/local/python3/lib/python3.5/site-packages/sqlalchemy/engine/default.py", line 507, in do_execute
    cursor.execute(statement, parameters)
sqlalchemy.exc.DatabaseError: (cx_Oracle.DatabaseError) ORA-01861: 文字与格式字符串不匹配 [SQL: 'INSERT INTO tbl_trans_things_num_temp (station_name, per_box_num, box_num, order_date, import_by) VALUES (:station_name, :per_box_num, :box_num, :order_date, :import_by) RETURNING tbl_trans_things_num_temp.things_id INTO :ret_0'] [parameters: {'import_by': 'admin', 'per_box_num': 0.0, 'ret_0': <cx_Oracle.STRING with value [None, None, None, None, None, None, None, None, None, None, None, None, None, None, None, None, None, None, None, None,  ... (30 characters truncated) ... None, None, None, None, None, None, None, None, None, None, None, None, None, None, None, None, None, None, None, None, None, None, None, None, None]>, 'station_name': '白各庄', 'box_num': 0.0, 'order_date': '2018-02-24'}] (Background on this error at: http://sqlalche.me/e/4xp6)
60.24.91.182 - - [24/Feb/2018 13:44:15] "POST /admin/trans/add/ HTTP/1.1" 500 -
Traceback (most recent call last):
  File "/usr/local/python3/lib/python3.5/site-packages/flask/app.py", line 1997, in __call__
    return self.wsgi_app(environ, start_response)
  File "/usr/local/python3/lib/python3.5/site-packages/flask/app.py", line 1985, in wsgi_app
    response = self.handle_exception(e)
  File "/usr/local/python3/lib/python3.5/site-packages/flask/app.py", line 1540, in handle_exception
    reraise(exc_type, exc_value, tb)
  File "/usr/local/python3/lib/python3.5/site-packages/flask/_compat.py", line 33, in reraise
    raise value
  File "/usr/local/python3/lib/python3.5/site-packages/flask/app.py", line 1982, in wsgi_app
    response = self.full_dispatch_request()
  File "/usr/local/python3/lib/python3.5/site-packages/flask/app.py", line 1614, in full_dispatch_request
    rv = self.handle_user_exception(e)
  File "/usr/local/python3/lib/python3.5/site-packages/flask/app.py", line 1517, in handle_user_exception
    reraise(exc_type, exc_value, tb)
  File "/usr/local/python3/lib/python3.5/site-packages/flask/_compat.py", line 33, in reraise
    raise value
  File "/usr/local/python3/lib/python3.5/site-packages/flask/app.py", line 1612, in full_dispatch_request
    rv = self.dispatch_request()
  File "/usr/local/python3/lib/python3.5/site-packages/flask/app.py", line 1598, in dispatch_request
    return self.view_functions[rule.endpoint](**req.view_args)
  File "/usr/local/nginx/html/solution_project/app/admin/views.py", line 48, in decorated_function
    return f(*args, **kwargs)
  File "/usr/local/nginx/html/solution_project/app/admin/views.py", line 70, in decorated_function
    return f(*args, **kwargs)
  File "/usr/local/nginx/html/solution_project/app/admin/views.py", line 565, in trans_add
    db.session.commit()
  File "/usr/local/python3/lib/python3.5/site-packages/sqlalchemy/orm/scoping.py", line 153, in do
    return getattr(self.registry(), name)(*args, **kwargs)
  File "/usr/local/python3/lib/python3.5/site-packages/sqlalchemy/orm/session.py", line 943, in commit
    self.transaction.commit()
  File "/usr/local/python3/lib/python3.5/site-packages/sqlalchemy/orm/session.py", line 467, in commit
    self._prepare_impl()
  File "/usr/local/python3/lib/python3.5/site-packages/sqlalchemy/orm/session.py", line 447, in _prepare_impl
    self.session.flush()
  File "/usr/local/python3/lib/python3.5/site-packages/sqlalchemy/orm/session.py", line 2243, in flush
    self._flush(objects)
  File "/usr/local/python3/lib/python3.5/site-packages/sqlalchemy/orm/session.py", line 2369, in _flush
    transaction.rollback(_capture_exception=True)
  File "/usr/local/python3/lib/python3.5/site-packages/sqlalchemy/util/langhelpers.py", line 66, in __exit__
    compat.reraise(exc_type, exc_value, exc_tb)
  File "/usr/local/python3/lib/python3.5/site-packages/sqlalchemy/util/compat.py", line 187, in reraise
    raise value
  File "/usr/local/python3/lib/python3.5/site-packages/sqlalchemy/orm/session.py", line 2333, in _flush
    flush_context.execute()
  File "/usr/local/python3/lib/python3.5/site-packages/sqlalchemy/orm/unitofwork.py", line 391, in execute
    rec.execute(self)
  File "/usr/local/python3/lib/python3.5/site-packages/sqlalchemy/orm/unitofwork.py", line 556, in execute
    uow
  File "/usr/local/python3/lib/python3.5/site-packages/sqlalchemy/orm/persistence.py", line 181, in save_obj
    mapper, table, insert)
  File "/usr/local/python3/lib/python3.5/site-packages/sqlalchemy/orm/persistence.py", line 866, in _emit_insert_statements
    execute(statement, params)
  File "/usr/local/python3/lib/python3.5/site-packages/sqlalchemy/engine/base.py", line 948, in execute
    return meth(self, multiparams, params)
  File "/usr/local/python3/lib/python3.5/site-packages/sqlalchemy/sql/elements.py", line 269, in _execute_on_connection
    return connection._execute_clauseelement(self, multiparams, params)
  File "/usr/local/python3/lib/python3.5/site-packages/sqlalchemy/engine/base.py", line 1060, in _execute_clauseelement
    compiled_sql, distilled_params
  File "/usr/local/python3/lib/python3.5/site-packages/sqlalchemy/engine/base.py", line 1200, in _execute_context
    context)
  File "/usr/local/python3/lib/python3.5/site-packages/sqlalchemy/engine/base.py", line 1413, in _handle_dbapi_exception
    exc_info
  File "/usr/local/python3/lib/python3.5/site-packages/sqlalchemy/util/compat.py", line 203, in raise_from_cause
    reraise(type(exception), exception, tb=exc_tb, cause=cause)
  File "/usr/local/python3/lib/python3.5/site-packages/sqlalchemy/util/compat.py", line 186, in reraise
    raise value.with_traceback(tb)
  File "/usr/local/python3/lib/python3.5/site-packages/sqlalchemy/engine/base.py", line 1193, in _execute_context
    context)
  File "/usr/local/python3/lib/python3.5/site-packages/sqlalchemy/engine/default.py", line 507, in do_execute
    cursor.execute(statement, parameters)
sqlalchemy.exc.DatabaseError: (cx_Oracle.DatabaseError) ORA-01861: 文字与格式字符串不匹配 [SQL: 'INSERT INTO tbl_trans_things_num_temp (station_name, per_box_num, box_num, order_date, import_by) VALUES (:station_name, :per_box_num, :box_num, :order_date, :import_by) RETURNING tbl_trans_things_num_temp.things_id INTO :ret_0'] [parameters: {'import_by': 'admin', 'per_box_num': 0.0, 'ret_0': <cx_Oracle.STRING with value [None, None, None, None, None, None, None, None, None, None, None, None, None, None, None, None, None, None, None, None,  ... (30 characters truncated) ... None, None, None, None, None, None, None, None, None, None, None, None, None, None, None, None, None, None, None, None, None, None, None, None, None]>, 'station_name': '白各庄', 'box_num': 0.0, 'order_date': '2018-02-24'}] (Background on this error at: http://sqlalche.me/e/4xp6)
60.24.91.182 - - [24/Feb/2018 13:44:15] "POST /admin/trans/add/ HTTP/1.1" 500 -
